<?xml version="1.0" ?>
<robot name="mobile_manipulator">
    <!--################################# BASE #####################################-->
    <link name="base_link">
        <inertial>
            <origin xyz="0.0030946 4.78250032638821E-11 0.053305" rpy="0 0 0" />
            <mass value="47.873" />
            <inertia ixx="0.774276574699151" ixy="-1.03781944357671E-10" ixz="0.00763014265820928" iyy="1.64933255189991" iyz="1.09578155845563E-12" izz="2.1239326987473" />
        </inertial>
        <visual>
            <origin xyz="0 0 0" rpy="1.5707963267949 0 3.14" />
            <geometry>
                <mesh filename="package://mobile_manipulator_body/meshes/robot_base.stl" />
            </geometry>
            <material name="">
                <color rgba="0 0 0 1.0" />
            </material>
        </visual>
        <collision>
            <origin xyz="0 0 0" rpy="1.5707963267949 0 3.14" />
            <geometry>
                <mesh filename="package://mobile_manipulator_body/meshes/robot_base.stl" />
            </geometry>
        </collision>
    </link>
    <link name="front_left_wheel">
        <inertial>
            <origin xyz="-4.1867E-18 0.0068085 -1.65658661799998E-18" rpy="0 0 0" />
            <mass value="2.6578" />
            <inertia ixx="0.00856502765719703" ixy="1.5074118157338E-19" ixz="-4.78150098725052E-19" iyy="0.013670640432096" iyz="-2.68136447099727E-19" izz="0.00856502765719703" />
        </inertial>
        <visual>
            <origin xyz="0 0.018 0" rpy="-1.5707963267949 -1.5707963267949 -1.5707963267949" />
            <geometry>
                <mesh filename="package://mobile_manipulator_body/meshes/wheel.dae" />
            </geometry>
            <material name="">
                <color rgba="1.0 0.0 0.0 1" />
            </material>
        </visual>
        <collision>
            <origin xyz="0 0.018 0" rpy="-1.5707963267949 -1.5707963267949 -1.5707963267949" />
            <geometry>
                <mesh filename="package://mobile_manipulator_body/meshes/wheel.dae" />
            </geometry>
        </collision>
    </link>
    <link name="front_right_wheel">
        <inertial>
            <origin xyz="-4.1867E-18 0.0068085 -1.65658661799998E-18" rpy="0 0 0" />
            <mass value="2.6578" />
            <inertia ixx="0.00856502765719703" ixy="1.5074118157338E-19" ixz="-4.78150098725052E-19" iyy="0.013670640432096" iyz="-2.68136447099727E-19" izz="0.00856502765719703" />
        </inertial>
        <visual>
            <origin xyz="0 -0.018 0" rpy="-1.5707963267949 -1.5707963267949 -1.5707963267949" />
            <geometry>
                <mesh filename="package://mobile_manipulator_body/meshes/wheel.dae" />
            </geometry>
            <material name="">
                <color rgba="1.0 0.0 0.0 1" />
            </material>
        </visual>
        <collision>
            <origin xyz="0 -0.018 0" rpy="-1.5707963267949 -1.5707963267949 -1.5707963267949" />
            <geometry>
                <mesh filename="package://mobile_manipulator_body/meshes/wheel.dae" />
            </geometry>
        </collision>
    </link>
    <link name="rear_left_wheel">
        <inertial>
            <origin xyz="-4.1867E-18 0.0068085 -1.65658661799998E-18" rpy="0 0 0" />
            <mass value="2.6578" />
            <inertia ixx="0.00856502765719703" ixy="1.5074118157338E-19" ixz="-4.78150098725052E-19" iyy="0.013670640432096" iyz="-2.68136447099727E-19" izz="0.00856502765719703" />
        </inertial>
        <visual>
            <origin xyz="0 0.018 0" rpy="-1.5707963267949 -1.5707963267949 -1.5707963267949" />
            <geometry>
                <mesh filename="package://mobile_manipulator_body/meshes/wheel.dae" />
            </geometry>
            <material name="">
                <color rgba="1.0 0.0 0.0 1" />
            </material>
        </visual>
        <collision>
            <origin xyz="0 0.018 0" rpy="-1.5707963267949 -1.5707963267949 -1.5707963267949" />
            <geometry>
                <mesh filename="package://mobile_manipulator_body/meshes/wheel.dae" />
            </geometry>
        </collision>
    </link>
    <link name="rear_right_wheel">
        <inertial>
            <origin xyz="-4.1867E-18 0.0068085 -1.65658661799998E-18" rpy="0 0 0" />
            <mass value="2.6578" />
            <inertia ixx="0.00856502765719703" ixy="1.5074118157338E-19" ixz="-4.78150098725052E-19" iyy="0.013670640432096" iyz="-2.68136447099727E-19" izz="0.00856502765719703" />
        </inertial>
        <visual>
            <origin xyz="0 -0.018 0" rpy="-1.5707963267949 -1.5707963267949 -1.5707963267949" />
            <geometry>
                <mesh filename="package://mobile_manipulator_body/meshes/wheel.dae" />
            </geometry>
            <material name="">
                <color rgba="1.0 0.0 0.0 1" />
            </material>
        </visual>
        <collision>
            <origin xyz="0 -0.018 0" rpy="-1.5707963267949 -1.5707963267949 -1.5707963267949" />
            <geometry>
                <mesh filename="package://mobile_manipulator_body/meshes/wheel.dae" />
            </geometry>
        </collision>
    </link>
    <joint name="front_left_wheel_joint" type="continuous">
        <axis xyz="0 1 0" />
        <parent link="base_link" />
        <child link="front_left_wheel" />
        <origin rpy="0 0 0" xyz="0.220 0.250 0" />
    </joint>
    <joint name="front_right_wheel_joint" type="continuous">
        <axis xyz="0 1 0" />
        <parent link="base_link" />
        <child link="front_right_wheel" />
        <origin rpy="0 0 0" xyz="0.220 -0.250 0" />
    </joint>
    <joint name="rear_left_wheel_joint" type="continuous">
        <axis xyz="0 1 0" />
        <parent link="base_link" />
        <child link="rear_left_wheel" />
        <origin rpy="0 0 0" xyz="-0.220 0.250 0" />
    </joint>
    <joint name="rear_right_wheel_joint" type="continuous">
        <axis xyz="0 1 0" />
        <parent link="base_link" />
        <child link="rear_right_wheel" />
        <origin rpy="0 0 0" xyz="-0.220 -0.250 0" />
    </joint>
    <!--############################## ARM ########################################-->
    <link name="arm_base">
        <inertial>
            <origin xyz="7.7128E-09 -0.063005 -3.01969999961422E-08" rpy="0 0 0" />
            <mass value="1.6004" />
            <inertia ixx="0.00552196561445819" ixy="7.9550614501301E-10" ixz="-1.34378458924839E-09" iyy="0.00352397447953875" iyz="-1.10071809773382E-08" izz="0.00553739792746489" />
        </inertial>
        <visual>
            <origin xyz="0 0 0" rpy="0 0 0" />
            <geometry>
                <mesh filename="package://mobile_manipulator_body/meshes/arm_base.stl" />
            </geometry>
            <material name="">
                <color rgba="1.0 1.0 0.0 1" />
            </material>
        </visual>
        <collision>
            <origin xyz="0 0 0" rpy="0 0 0" />
            <geometry>
                <mesh filename="package://mobile_manipulator_body/meshes/arm_base.stl" />
            </geometry>
        </collision>
    </link>
    <link name="bicep">
        <inertial>
            <origin xyz="0.12821 3.5589E-06 0.052492" rpy="0 0 0" />
            <mass value="1.1198" />
            <inertia ixx="0.0012474" ixy="-5.4004E-07" ixz="-0.0013148" iyy="0.0072923" iyz="-1.8586E-07" izz="0.0068178" />
        </inertial>
        <visual>
            <origin xyz="0 0 0" rpy="0 -1.5708 0" />
            <geometry>
                <mesh filename="package://mobile_manipulator_body/meshes/bicep.stl" />
            </geometry>
            <material name="">
                <color rgba="1.0 1.0 0.0 1" />
            </material>
        </visual>
        <collision>
            <origin xyz="0 0 0" rpy="0 -1.5708 0" />
            <geometry>
                <mesh filename="package://mobile_manipulator_body/meshes/bicep.stl" />
            </geometry>
        </collision>
    </link>
    <link name="bottom_wrist">
        <inertial>
            <origin xyz="-9.1053E-08 -0.069257 -1.86629999995759E-07" rpy="0 0 0" />
            <mass value="0.27721" />
            <inertia ixx="0.00104290750143942" ixy="4.37155302268076E-09" ixz="-2.45049603914627E-09" iyy="0.000380518373895034" iyz="-7.56009835172156E-09" izz="0.00106006525067445" />
        </inertial>
        <visual>
            <origin xyz="0 0 0.13522" rpy="3.14 0 1.5708" />
            <geometry>
                <mesh filename="package://mobile_manipulator_body/meshes/wrist.stl" />
            </geometry>
            <material name="">
                <color rgba="1.0 1.0 0.0 1" />
            </material>
        </visual>
        <collision>
            <origin xyz="0 0 0.13522" rpy="3.14 0 1.5708" />
            <geometry>
                <mesh filename="package://mobile_manipulator_body/meshes/wrist.stl" />
            </geometry>
        </collision>
    </link>
    <link name="elbow">
        <inertial>
            <origin xyz="-0.11109 1.1476E-08 0.046469" rpy="0 0 0" />
            <mass value="0.84845" />
            <inertia ixx="0.00079656" ixy="-7.8011E-10" ixz="0.00053616" iyy="0.003576" iyz="4.6326E-10" izz="0.0033698" />
        </inertial>
        <visual>
            <origin xyz="0.0 0.05163 0.20994" rpy="0 -1.5708 0" />
            <geometry>
                <mesh filename="package://mobile_manipulator_body/meshes/elbow.stl" />
            </geometry>
            <material name="">
                <color rgba="1.0 1.0 0.0 1" />
            </material>
        </visual>
        <collision>
            <origin xyz="0.0 0.05163 0.20994" rpy="0 -1.5708 0" />
            <geometry>
                <mesh filename="package://mobile_manipulator_body/meshes/elbow.stl" />
            </geometry>
        </collision>
    </link>
    <link name="top_wrist">
        <inertial>
            <origin xyz="-9.1053E-08 -0.069257 -1.86629999995759E-07" rpy="0 0 0" />
            <mass value="0.27721" />
            <inertia ixx="0.00104290750143942" ixy="4.37155302268076E-09" ixz="-2.45049603914627E-09" iyy="0.000380518373895034" iyz="-7.56009835172156E-09" izz="0.00106006525067445" />
        </inertial>
        <visual>
            <origin xyz="0 0 0.13522" rpy="3.14 0 1.5708" />
            <geometry>
                <mesh filename="package://mobile_manipulator_body/meshes/wrist.stl" />
            </geometry>
            <material name="">
                <color rgba="1.0 1.0 0.0 1" />
            </material>
        </visual>
        <collision>
            <origin xyz="0 0 0.13522" rpy="3.14 0 1.5708" />
            <geometry>
                <mesh filename="package://mobile_manipulator_body/meshes/wrist.stl" />
            </geometry>
        </collision>
    </link>
    <joint name="arm_base_joint" type="continuous">
        <axis xyz="0 0 1" />
        <parent link="base_link" />
        <child link="arm_base" />
        <origin rpy="0 0 0" xyz="0.0 0.0 0.145" />
    </joint>
    <joint name="shoulder_joint" type="continuous">
        <axis xyz="0 1 0" />
        <parent link="arm_base" />
        <child link="bicep" />
        <origin rpy="0 0 1.5708" xyz="-0.05166 0.0 0.20271" />
    </joint>
    <joint name="bottom_wrist_joint" type="continuous">
        <axis xyz="0 1 0" />
        <parent link="bicep" />
        <child link="bottom_wrist" />
        <origin rpy="0 0 0" xyz="0.0 -0.05194 0.269" />
    </joint>
    <joint name="elbow_joint" type="continuous">
        <axis xyz="0 0 1" />
        <parent link="bottom_wrist" />
        <child link="elbow" />
        <origin rpy="0 0 0" xyz="0.0 0 0.13522" />
    </joint>
    <joint name="top_wrist_joint" type="continuous">
        <axis xyz="0 1 0" />
        <parent link="elbow" />
        <child link="top_wrist" />
        <origin rpy="0 0 0" xyz="0.0 0 0.20994" />
    </joint>
    <!--########################## BASE TRANSMISSIONS ############################################-->
    <transmission name="front_left_wheel_trans" type="SimpleTransmission">
        <type>transmission_interface/SimpleTransmission</type>
        <actuator name="front_left_wheel_motor">
            <hardwareInterface>hardware_interface/VelocityJointInterface</hardwareInterface>
            <mechanicalReduction>1</mechanicalReduction>
        </actuator>
        <joint name="front_left_wheel_joint">
            <hardwareInterface>hardware_interface/VelocityJointInterface</hardwareInterface>
        </joint>
    </transmission>
    <transmission name="front_right_wheel_trans" type="SimpleTransmission">
        <type>transmission_interface/SimpleTransmission</type>
        <actuator name="front_right_wheel_motor">
            <hardwareInterface>hardware_interface/VelocityJointInterface</hardwareInterface>
            <mechanicalReduction>1</mechanicalReduction>
        </actuator>
        <joint name="front_right_wheel_joint">
            <hardwareInterface>hardware_interface/VelocityJointInterface</hardwareInterface>
        </joint>
    </transmission>
    <transmission name="rear_left_wheel_trans" type="SimpleTransmission">
        <type>transmission_interface/SimpleTransmission</type>
        <actuator name="rear_left_wheel_motor">
            <hardwareInterface>hardware_interface/VelocityJointInterface</hardwareInterface>
            <mechanicalReduction>1</mechanicalReduction>
        </actuator>
        <joint name="rear_left_wheel_joint">
            <hardwareInterface>hardware_interface/VelocityJointInterface</hardwareInterface>
        </joint>
    </transmission>
    <transmission name="rear_right_wheel_trans" type="SimpleTransmission">
        <type>transmission_interface/SimpleTransmission</type>
        <actuator name="rear_right_wheel_motor">
            <hardwareInterface>hardware_interface/VelocityJointInterface</hardwareInterface>
            <mechanicalReduction>1</mechanicalReduction>
        </actuator>
        <joint name="rear_right_wheel_joint">
            <hardwareInterface>hardware_interface/VelocityJointInterface</hardwareInterface>
        </joint>
    </transmission>
    <!--########################## SENSORS ############################################-->
    <!--########################## logi_camera ############################################-->
    <link name="logi_camera_link">
        <inertial>
            <origin rpy="0 0 0" xyz="-0.017293584176189366 -2.4383966124928845e-05 0.020495008384212435" />
            <mass value="0.15033659991756945" />
            <inertia ixx="8.7e-05" ixy="0.0" ixz="-2e-05" iyy="7.2e-05" iyz="0.0" izz="0.000108" />
        </inertial>
        <visual>
            <origin rpy="1.57079632679 0 1.57079632679" xyz="0.009 0.02 0.07" />
            <geometry>
                <mesh filename="package://mobile_manipulator_body/meshes/depth.stl" scale="0.001 0.001 0.001" />
            </geometry>
            <material name="">
                <color rgba="0 0 0 1.0" />
            </material>
        </visual>
        <collision>
            <origin rpy="1.57079632679 0 1.57079632679" xyz="0.009 0.02 0.07" />
            <geometry>
                <mesh filename="package://mobile_manipulator_body/meshes/depth.stl" scale="0.001 0.001 0.001" />
            </geometry>
        </collision>
    </link>
    <joint name="logi_camera_joint" type="fixed">
        <origin rpy="0 -1.57079632679 0" xyz="-0.04 0 0.14" />
        <parent link="top_wrist" />
        <child link="logi_camera_link" />
    </joint>
    <joint name="camera_optical_joint" type="fixed">
        <parent link="logi_camera_link" />
        <child link="camera_link_optical" />
        <origin xyz="0 0 0" rpy="-1.57079632679 0 -1.57079632679" />
    </joint>
    <link name="camera_link_optical" />
    <gazebo reference="logi_camera_link">
        <sensor type="depth" name="camera">
            <origin xyz="0 0 0" rpy="0 0 0" />
            <visualize>false</visualize>
            <update_rate>40</update_rate>
            <plugin name="camera_plugin" filename="libgazebo_ros_openni_kinect.so">
                <baseline>0.2</baseline>
                <alwaysOn>true</alwaysOn>
                <!-- Keep this zero, update_rate in the parent <sensor> tag
            will control the frame rate. -->
                <updateRate>0.0</updateRate>
                <cameraName>camera_ir</cameraName>
                <imageTopicName>/camera/color/image_raw</imageTopicName>
                <cameraInfoTopicName>/camera/color/camera_info</cameraInfoTopicName>
                <depthImageTopicName>/camera/depth/image_raw</depthImageTopicName>
                <depthImageCameraInfoTopicName>/camera/depth/camera_info</depthImageCameraInfoTopicName>
                <pointCloudTopicName>/camera/depth/points</pointCloudTopicName>
                <frameName>camera_link_optical</frameName>
                <pointCloudCutoff>0.5</pointCloudCutoff>
                <pointCloudCutoffMax>3.0</pointCloudCutoffMax>
                <distortionK1>0</distortionK1>
                <distortionK2>0</distortionK2>
                <distortionK3>0</distortionK3>
                <distortionT1>0</distortionT1>
                <distortionT2>0</distortionT2>
                <CxPrime>0</CxPrime>
                <Cx>0</Cx>
                <Cy>0</Cy>
                <focalLength>0</focalLength>
                <hackBaseline>0</hackBaseline>
            </plugin>
        </sensor>
        <static>true</static>
        <plugin name="gazebo_ros_control">
            <robotNamespace>/</robotNamespace>
        </plugin>
    </gazebo>
    <!--########################## laser ############################################-->
    <link name="laser_link">
        <inertial>
            <origin rpy="0 0 0" xyz="0.0034625894668202637 0.00010269753328175684 0.02092482852234422" />
            <mass value="0.06839266167546813" />
            <inertia ixx="3.8e-05" ixy="0.0" ixz="-2e-06" iyy="3.9e-05" iyz="-0.0" izz="5.5e-05" />
        </inertial>
        <visual>
            <origin rpy="0 0 0" xyz="0 0 -0.03" />
            <geometry>
                <mesh filename="package://mobile_manipulator_body/meshes/rplidar_a2.stl" scale="0.001 0.001 0.001" />
            </geometry>
            <material name="" />
        </visual>
        <collision>
            <origin rpy="0 0 0" xyz="0 0 -0.03" />
            <geometry>
                <mesh filename="package://mobile_manipulator_body/meshes/rplidar_a2.stl" scale="0.001 0.001 0.001" />
            </geometry>
        </collision>
    </link>
    <joint name="laser_joint" type="fixed">
        <axis xyz="0 1 0" />
        <origin xyz="0.20 0.0 0.18" rpy="0 0 0" />
        <parent link="base_link" />
        <child link="laser_link" />
    </joint>
    <gazebo reference="laser_link">
        <sensor type="ray" name="laser">
            <pose>0 0 0 0 0 0</pose>
            <visualize>false</visualize>
            <update_rate>40</update_rate>
            <ray>
                <scan>
                    <horizontal>
                        <samples>720</samples>
                        <resolution>1</resolution>
                        <min_angle>-1.57079632679</min_angle>
                        <max_angle>1.57079632679</max_angle>
                    </horizontal>
                </scan>
                <range>
                    <min>0.10</min>
                    <max>30.0</max>
                    <resolution>0.01</resolution>
                </range>
            </ray>
            <plugin name="gazebo_ros_head_hokuyo_controller" filename="libgazebo_ros_laser.so">
                <topicName>/scan</topicName>
                <frameName>laser_link</frameName>
            </plugin>
        </sensor>
    </gazebo>
    <!--########################## IMU ############################################-->
    <link name="imu_link">
        <inertial>
            <origin rpy="0 0 0" xyz="0.0034625894668202637 0.00010269753328175684 0.02092482852234422" />
            <mass value="0.06839266167546813" />
            <inertia ixx="3.8e-05" ixy="0.0" ixz="-2e-06" iyy="3.9e-05" iyz="-0.0" izz="5.5e-05" />
        </inertial>
        <visual>
            <origin rpy="0 0 0" xyz="0 0 -0.03" />
            <geometry>
                <mesh filename="package://mobile_manipulator_body/meshes/BNO055.stl" scale="0.001 0.001 0.001" />
            </geometry>
            <material name="" />
        </visual>
        <collision>
            <origin rpy="0 0 0" xyz="0 0 -0.03" />
            <geometry>
                <mesh filename="package://mobile_manipulator_body/meshes/BNO055.stl" scale="0.001 0.001 0.001" />
            </geometry>
        </collision>
    </link>
    <joint name="imu_joint" type="fixed">
        <axis xyz="1 0 0" />
        <!-- 0 1 0 -->
        <origin xyz="0.20 0.14 0.18" />
        <parent link="base_link" />
        <child link="imu_link" />
    </joint>
    <gazebo reference="imu_link">
        <gravity>true</gravity>
        <sensor name="imu_sensor" type="imu">
            <always_on>true</always_on>
            <update_rate>100</update_rate>
            <visualize>true</visualize>
            <topic>__default_topic__</topic>
            <plugin filename="libgazebo_ros_imu_sensor.so" name="imu_plugin">
                <topicName>imu_data</topicName>
                <bodyName>imu_link</bodyName>
                <updateRateHZ>10.0</updateRateHZ>
                <gaussianNoise>0.0</gaussianNoise>
                <xyzOffset>0 0 0</xyzOffset>
                <rpyOffset>0 0 0</rpyOffset>
                <frameName>imu_link</frameName>
                <initialOrientationAsReference>false</initialOrientationAsReference>
            </plugin>
            <pose>0 0 0 0 0 0</pose>
        </sensor>
    </gazebo>
    <!--################################ ARM TRANSIMISSIONS ######################################-->
    <transmission name="arm_base_trans" type="SimpleTransmission">
        <type>transmission_interface/SimpleTransmission</type>
        <actuator name="arm_base_motor">
            <hardwareInterface>hardware_interface/PositionJointInterface</hardwareInterface>
            <mechanicalReduction>1</mechanicalReduction>
        </actuator>
        <joint name="arm_base_joint">
            <hardwareInterface>hardware_interface/PositionJointInterface</hardwareInterface>
        </joint>
    </transmission>
    <transmission name="shoulder_trans" type="SimpleTransmission">
        <type>transmission_interface/SimpleTransmission</type>
        <actuator name="shoulder_motor">
            <hardwareInterface>hardware_interface/PositionJointInterface</hardwareInterface>
            <mechanicalReduction>1</mechanicalReduction>
        </actuator>
        <joint name="shoulder_joint">
            <hardwareInterface>hardware_interface/PositionJointInterface</hardwareInterface>
        </joint>
    </transmission>
    <transmission name="bottom_wrist_trans" type="SimpleTransmission">
        <type>transmission_interface/SimpleTransmission</type>
        <actuator name="bottom_wrist_motor">
            <hardwareInterface>hardware_interface/PositionJointInterface</hardwareInterface>
            <mechanicalReduction>1</mechanicalReduction>
        </actuator>
        <joint name="bottom_wrist_joint">
            <hardwareInterface>hardware_interface/PositionJointInterface</hardwareInterface>
        </joint>
    </transmission>
    <transmission name="elbow_trans" type="SimpleTransmission">
        <type>transmission_interface/SimpleTransmission</type>
        <actuator name="elbow_motor">
            <hardwareInterface>hardware_interface/PositionJointInterface</hardwareInterface>
            <mechanicalReduction>1</mechanicalReduction>
        </actuator>
        <joint name="elbow_joint">
            <hardwareInterface>hardware_interface/PositionJointInterface</hardwareInterface>
        </joint>
    </transmission>
    <transmission name="top_wrist_trans" type="SimpleTransmission">
        <type>transmission_interface/SimpleTransmission</type>
        <actuator name="top_wrist_motor">
            <hardwareInterface>hardware_interface/PositionJointInterface</hardwareInterface>
            <mechanicalReduction>1</mechanicalReduction>
        </actuator>
        <joint name="top_wrist_joint">
            <hardwareInterface>hardware_interface/PositionJointInterface</hardwareInterface>
        </joint>
    </transmission>
    <!--######################################################################-->
    <gazebo>
        <plugin name="gazebo_ros_control" filename="libgazebo_ros_control.so">
            <robotNamespace>/</robotNamespace>
            <controlPeriod>0.001</controlPeriod>
            <legacyModeNS>false</legacyModeNS>
        </plugin>
    </gazebo>
    <!--######################################################################-->
    <gazebo>
        <plugin name="joint_state_publisher" filename="libgazebo_ros_joint_state_publisher.so">
            <jointName>arm_base_joint, shoulder_joint, bottom_wrist_joint, elbow_joint, bottom_wrist_joint</jointName>
        </plugin>
    </gazebo>
    <!--######################################################################-->
    <!--######################################################################-->
    <gazebo>
        <plugin name="p3d_base_controller" filename="libgazebo_ros_p3d.so">
            <alwaysOn>true</alwaysOn>
            <updateRate>50.0</updateRate>
            <bodyName>base_link</bodyName>
            <topicName>base_truth_odom</topicName>
            <gaussianNoise>0.01</gaussianNoise>
            <frameName>world</frameName>
            <xyzOffsets>0 0 0</xyzOffsets>
            <rpyOffsets>0 0 0</rpyOffsets>
        </plugin>
    </gazebo>
    <!--######################################################################-->
    <gazebo reference="base_link">
        <material>Gazebo/DarkGrey</material>
    </gazebo>
    <gazebo reference="front_left_wheel">
        <mu1 value="1.0" />
        <mu2 value="1.0" />
        <kp value="10000000.0" />
        <kd value="1.0" />
        <fdir1 value="1 0 0" />
    </gazebo>
    <gazebo reference="front_right_wheel">
        <mu1 value="1.0" />
        <mu2 value="1.0" />
        <kp value="10000000.0" />
        <kd value="1.0" />
        <fdir1 value="1 0 0" />
    </gazebo>
    <gazebo reference="rear_left_wheel">
        <mu1 value="1.0" />
        <mu2 value="1.0" />
        <kp value="10000000.0" />
        <kd value="1.0" />
        <fdir1 value="1 0 0" />
    </gazebo>
    <gazebo reference="rear_right_wheel">
        <mu1 value="1.0" />
        <mu2 value="1.0" />
        <kp value="10000000.0" />
        <kd value="1.0" />
        <fdir1 value="1 0 0" />
    </gazebo>
    <gazebo reference="laser_link">
        <material>Gazebo/Grey</material>
    </gazebo>
    <gazebo reference="imu_link">
        <material>Gazebo/Blue</material>
    </gazebo>
    <!--######################################################################-->
    <gazebo reference="arm_base">
        <material>Gazebo/Yellow</material>
    </gazebo>
    <gazebo reference="bicep">
        <material>Gazebo/Yellow</material>
    </gazebo>
    <gazebo reference="bottom_wrist">
        <material>Gazebo/Yellow</material>
    </gazebo>
    <gazebo reference="elbow">
        <material>Gazebo/Yellow</material>
    </gazebo>
    <gazebo reference="top_wrist">
        <material>Gazebo/Yellow</material>
    </gazebo>
    <!--######################################################################-->
    <gazebo reference="logi_camera_link">
        <material>Gazebo/DarkGrey</material>
    </gazebo>
</robot>

